{"errorMessage": "An error occurred (AccessDenied) when calling the PutObject operation: User: arn:aws:sts::221025630675:assumed-role/create-gallery-dev-us-west-2-lambdaRole/mylg-v12-create-gallery-dev is not authorized to perform: s3:PutObject on resource: \"arn:aws:s3:::mylg-files-v12/projects/f20d9620-1379-475b-928e-733ec953af73/gallery/design-boardsvg/images/exported_image_1.png\" because no identity-based policy allows the s3:PutObject action", "errorType": "ClientError", "requestId": "90f432a1-2ea9-40e1-9b74-486dde2e8f32", "stackTrace": ["  File \"/var/task/lambda_function.py\", line 330, in lambda_handler\n    return process_request(body, cors_headers)\n", "  File \"/var/task/lambda_function.py\", line 201, in process_request\n    svg_content, image_urls = extract_images(svg_content, base_path, bucket)\n", "  File \"/var/task/lambda_function.py\", line 51, in extract_images\n    s3.put_object(\n", "  File \"/var/lang/lib/python3.12/site-packages/botocore/client.py\", line 602, in _api_call\n    return self._make_api_call(operation_name, kwargs)\n", "  File \"/var/lang/lib/python3.12/site-packages/botocore/context.py\", line 123, in wrapper\n    return func(*args, **kwargs)\n", "  File \"/var/lang/lib/python3.12/site-packages/botocore/client.py\", line 1078, in _make_api_call\n    raise error_class(parsed_response, operation_name)\n"]}